Workbook
Name Backup_Storage: '[1]Technical Details (IaaS)'!#REF!
Name Backup_Storage: '[1]Technical Details (IaaS)'!#REF!
Name Backup_Storage: '[1]Technical Details (IaaS)'!#REF!
Name Backup_Storage: '[1]Technical Details (IaaS)'!#REF!
Name field_req_Post: '[1]Request Summary'!#REF!
Name field_req_Post: '[1]Request Summary'!#REF!
Name field_req_Post: '[1]Request Summary'!#REF!
Name field_req_Post: '[1]Request Summary'!#REF!
Name Shared_Storage: '[1]Technical Details (IaaS)'!#REF!
Name Shared_Storage: '[1]Technical Details (IaaS)'!#REF!
Name Shared_Storage: '[1]Technical Details (IaaS)'!#REF!
Name Shared_Storage: '[1]Technical Details (IaaS)'!#REF!

Sheet svc
A1: App No. | B1: vLan | C1: Zone | D1: zone tag | E1: upstream | F1: to zone | G1: http | H1: https | I1: app_name | J1: service description | K1: call from external | L1: call from trust | M1: call from dmz | N1: call to external | O1: call to trust | P1: call to dmz | Q1: others | R1: application type | S1: exposed kong(btw dmz/trust) http url | T1: exposed kong(btw dmz/trust) https url | U1: exposed kong(from ext to dmz) http url | V1: exposed kong(from ext to dmz) https url | W1: Linkagee for DAS (Non-Prod)
A2: 1 | B2: v504 | C2: DMZ (TSP) | D2: dmz | E2: ="k8s-"&D2 -> k8s-dmz | F2: =IF(D2="dmz","trust","dmz") -> trust | G2: 31011 | H2: 32011 | I2: bes_signalr_server | J2: SignalR for all internal portal | K2: web socket from TSP/Gov | L2: api / web socket | M2: api / web socket | N2: web socket call TSP/Gov web clients | P2: web socket | R2: web_socket + rest_api | S2: =IF(LEN(B2)>0,IF(ISNUMBER(FIND("api",CONCATENATE(L2,M2))),CONCATENATE("http://ltm",MID(B2,2,15),":8000/",D2,MID(B2,2,15),"/",$I2),""),"") -> http://ltm504:8000/dmz504/bes_signalr_server | T2: =IF(LEN(B2)>0,IF(ISNUMBER(FIND("api",CONCATENATE(L2,M2))),CONCATENATE("https://ltm",MID(B2,2,15),":8443/",D2,MID(B2,2,15),"/",$I2),""),"") -> https://ltm504:8443/dmz504/bes_signalr_server | U2: =IF(D2="dmz",IF(ISNUMBER(FIND("api",K2)),CONCATENATE("http://",B2,".bes_ext_api:8000/",D2,MID(B2,2,15),"/",I2,""),""),"") | V2: =IF(D2="dmz",IF(ISNUMBER(FIND("api",K2)),CONCATENATE("https://",B2,".bes_ext_api:8443/",D2,MID(B2,2,15),"/",I2,""),""),"")
A3: 2 | B3: v504 | C3: DMZ (TSP) | D3: dmz | E3: ="k8s-"&D3 -> k8s-dmz | F3: =IF(D3="dmz","trust","dmz") -> trust | G3: 31026 | H3: 32026 | I3: bes_wmm | J3: Middleware for customer web and mobile app to call | K3: api call from TSP/Internet | L3: api | M3: api | O3: api | P3: api | R3: rest_api | S3: =IF(LEN(B3)>0,IF(ISNUMBER(FIND("api",CONCATENATE(L3,M3))),CONCATENATE("http://ltm",MID(B3,2,15),":8000/",D3,MID(B3,2,15),"/",$I3),""),"") -> http://ltm504:8000/dmz504/bes_wmm | T3: =IF(LEN(B3)>0,IF(ISNUMBER(FIND("api",CONCATENATE(L3,M3))),CONCATENATE("https://ltm",MID(B3,2,15),":8443/",D3,MID(B3,2,15),"/",$I3),""),"") -> https://ltm504:8443/dmz504/bes_wmm | U3: =IF(D3="dmz",IF(ISNUMBER(FIND("api",K3)),CONCATENATE("http://",B3,".bes_ext_api:8000/",D3,MID(B3,2,15),"/",I3,""),""),"") -> http://v504.bes_ext_api:8000/dmz504/bes_wmm | V3: =IF(D3="dmz",IF(ISNUMBER(FIND("api",K3)),CONCATENATE("https://",B3,".bes_ext_api:8443/",D3,MID(B3,2,15),"/",I3,""),""),"") -> https://v504.bes_ext_api:8443/dmz504/bes_wmm
A4: 116 | B4: v804 | C4: DMZ (Internet) | D4: dmz | E4: ="k8s-"&D4 -> k8s-dmz | F4: =IF(D4="dmz","trust","dmz") -> trust | G4: 31026 | H4: 32026 | I4: bes_wmm | J4: Middleware for customer web and mobile app to call | K4: api call from TSP/Internet | L4: api | M4: api | O4: api | P4: api | R4: rest_api | S4: =IF(LEN(B4)>0,IF(ISNUMBER(FIND("api",CONCATENATE(L4,M4))),CONCATENATE("http://ltm",MID(B4,2,15),":8000/",D4,MID(B4,2,15),"/",$I4),""),"") -> http://ltm804:8000/dmz804/bes_wmm | T4: =IF(LEN(B4)>0,IF(ISNUMBER(FIND("api",CONCATENATE(L4,M4))),CONCATENATE("https://ltm",MID(B4,2,15),":8443/",D4,MID(B4,2,15),"/",$I4),""),"") -> https://ltm804:8443/dmz804/bes_wmm | U4: =IF(D4="dmz",IF(ISNUMBER(FIND("api",K4)),CONCATENATE("http://",B4,".bes_ext_api:8000/",D4,MID(B4,2,15),"/",I4,""),""),"") -> http://v804.bes_ext_api:8000/dmz804/bes_wmm | V4: =IF(D4="dmz",IF(ISNUMBER(FIND("api",K4)),CONCATENATE("https://",B4,".bes_ext_api:8443/",D4,MID(B4,2,15),"/",I4,""),""),"") -> https://v804.bes_ext_api:8443/dmz804/bes_wmm
A5: 3 | B5: v504 | C5: DMZ (TSP) & DMZ (Gov) | D5: dmz | E5: ="k8s-"&D5 -> k8s-dmz | F5: =IF(D5="dmz","trust","dmz") -> trust | G5: 31010 | H5: 32010 | I5: bescore_portal | J5: BES Core portal | K5: web access from TSP/Gov | O5: api | R5: web portal | S5: =IF(LEN(B5)>0,IF(ISNUMBER(FIND("api",CONCATENATE(L5,M5))),CONCATENATE("http://ltm",MID(B5,2,15),":8000/",D5,MID(B5,2,15),"/",$I5),""),"") | T5: =IF(LEN(B5)>0,IF(ISNUMBER(FIND("api",CONCATENATE(L5,M5))),CONCATENATE("https://ltm",MID(B5,2,15),":8443/",D5,MID(B5,2,15),"/",$I5),""),"") | U5: =IF(D5="dmz",IF(ISNUMBER(FIND("api",K5)),CONCATENATE("http://",B5,".bes_ext_api:8000/",D5,MID(B5,2,15),"/",I5,""),""),"") | V5: =IF(D5="dmz",IF(ISNUMBER(FIND("api",K5)),CONCATENATE("https://",B5,".bes_ext_api:8443/",D5,MID(B5,2,15),"/",I5,""),""),"")
A6: 117 | B6: v504 | C6: DMZ (TSP) & DMZ (Gov) | D6: dmz | E6: ="k8s-"&D6 -> k8s-dmz | F6: =IF(D6="dmz","trust","dmz") -> trust | G6: 31010 | H6: 32010 | I6: bescore_portal | J6: BES Core portal | K6: web access from TSP/Gov | O6: api | R6: web portal | S6: =IF(LEN(B6)>0,IF(ISNUMBER(FIND("api",CONCATENATE(L6,M6))),CONCATENATE("http://ltm",MID(B6,2,15),":8000/",D6,MID(B6,2,15),"/",$I6),""),"") | T6: =IF(LEN(B6)>0,IF(ISNUMBER(FIND("api",CONCATENATE(L6,M6))),CONCATENATE("https://ltm",MID(B6,2,15),":8443/",D6,MID(B6,2,15),"/",$I6),""),"") | U6: =IF(D6="dmz",IF(ISNUMBER(FIND("api",K6)),CONCATENATE("http://",B6,".bes_ext_api:8000/",D6,MID(B6,2,15),"/",I6,""),""),"") | V6: =IF(D6="dmz",IF(ISNUMBER(FIND("api",K6)),CONCATENATE("https://",B6,".bes_ext_api:8443/",D6,MID(B6,2,15),"/",I6,""),""),"")
A7: 4 | B7: v504 | C7: DMZ (TSP) & DMZ (Gov) | D7: dmz | E7: ="k8s-"&D7 -> k8s-dmz | F7: =IF(D7="dmz","trust","dmz") -> trust | G7: 31028 | H7: 32028 | I7: ccms_portal | J7: BES CCMS Portal | K7: web access from TSP/Gov | O7: api | R7: web portal | S7: =IF(LEN(B7)>0,IF(ISNUMBER(FIND("api",CONCATENATE(L7,M7))),CONCATENATE("http://ltm",MID(B7,2,15),":8000/",D7,MID(B7,2,15),"/",$I7),""),"") | T7: =IF(LEN(B7)>0,IF(ISNUMBER(FIND("api",CONCATENATE(L7,M7))),CONCATENATE("https://ltm",MID(B7,2,15),":8443/",D7,MID(B7,2,15),"/",$I7),""),"") | U7: =IF(D7="dmz",IF(ISNUMBER(FIND("api",K7)),CONCATENATE("http://",B7,".bes_ext_api:8000/",D7,MID(B7,2,15),"/",I7,""),""),"") | V7: =IF(D7="dmz",IF(ISNUMBER(FIND("api",K7)),CONCATENATE("https://",B7,".bes_ext_api:8443/",D7,MID(B7,2,15),"/",I7,""),""),"")
A8: 118 | B8: v504 | C8: DMZ (TSP) & DMZ (Gov) | D8: dmz | E8: ="k8s-"&D8 -> k8s-dmz | F8: =IF(D8="dmz","trust","dmz") -> trust | G8: 31028 | H8: 32028 | I8: ccms_portal | J8: BES CCMS Portal | K8: web access from TSP/Gov | O8: api | R8: web portal | S8: =IF(LEN(B8)>0,IF(ISNUMBER(FIND("api",CONCATENATE(L8,M8))),CONCATENATE("http://ltm",MID(B8,2,15),":8000/",D8,MID(B8,2,15),"/",$I8),""),"") | T8: =IF(LEN(B8)>0,IF(ISNUMBER(FIND("api",CONCATENATE(L8,M8))),CONCATENATE("https://ltm",MID(B8,2,15),":8443/",D8,MID(B8,2,15),"/",$I8),""),"") | U8: =IF(D8="dmz",IF(ISNUMBER(FIND("api",K8)),CONCATENATE("http://",B8,".bes_ext_api:8000/",D8,MID(B8,2,15),"/",I8,""),""),"") | V8: =IF(D8="dmz",IF(ISNUMBER(FIND("api",K8)),CONCATENATE("https://",B8,".bes_ext_api:8443/",D8,MID(B8,2,15),"/",I8,""),""),"")
A9: 5 | B9: v904 | C9: DMZ (Gov) | D9: dmz | E9: ="k8s-"&D9 -> k8s-dmz | F9: =IF(D9="dmz","trust","dmz") -> trust | G9: 31211 | H9: 32211 | I9: ccs_middleware | J9: app to upload file to CCS FTP (ext) | L9: api | N9: File upload to CCS's FTP | O9: api | R9: rest_api | S9: =IF(LEN(B9)>0,IF(ISNUMBER(FIND("api",CONCATENATE(L9,M9))),CONCATENATE("http://ltm",MID(B9,2,15),":8000/",D9,MID(B9,2,15),"/",$I9),""),"") -> http://ltm904:8000/dmz904/ccs_middleware | T9: =IF(LEN(B9)>0,IF(ISNUMBER(FIND("api",CONCATENATE(L9,M9))),CONCATENATE("https://ltm",MID(B9,2,15),":8443/",D9,MID(B9,2,15),"/",$I9),""),"") -> https://ltm904:8443/dmz904/ccs_middleware | U9: =IF(D9="dmz",IF(ISNUMBER(FIND("api",K9)),CONCATENATE("http://",B9,".bes_ext_api:8000/",D9,MID(B9,2,15),"/",I9,""),""),"") | V9: =IF(D9="dmz",IF(ISNUMBER(FIND("api",K9)),CONCATENATE("https://",B9,".bes_ext_api:8443/",D9,MID(B9,2,15),"/",I9,""),""),"")
A10: 6 | B10: v630 | C10: DMZ (DAS) | D10: dmz | E10: ="k8s-"&D10 -> k8s-dmz | F10: =IF(D10="dmz","trust","dmz") -> trust | G10: 31119 | H10: 32119 | I10: das_middleware | J10: DAS middleware | K10: api call from DAS | L10: api | N10: api call DAS API | O10: api | Q10: Pulsar, Object Storage | R10: rest_api | S10: =IF(LEN(B10)>0,IF(ISNUMBER(FIND("api",CONCATENATE(L10,M10))),CONCATENATE("http://ltm",MID(B10,2,15),":8000/",D10,MID(B10,2,15),"/",$I10),""),"") -> http://ltm630:8000/dmz630/das_middleware | T10: =IF(LEN(B10)>0,IF(ISNUMBER(FIND("api",CONCATENATE(L10,M10))),CONCATENATE("https://ltm",MID(B10,2,15),":8443/",D10,MID(B10,2,15),"/",$I10),""),"") -> https://ltm630:8443/dmz630/das_middleware | U10: =IF(D10="dmz",IF(ISNUMBER(FIND("api",K10)),CONCATENATE("http://",B10,".bes_ext_api:8000/",D10,MID(B10,2,15),"/",I10,""),""),"") -> http://v630.bes_ext_api:8000/dmz630/das_middleware | V10: =IF(D10="dmz",IF(ISNUMBER(FIND("api",K10)),CONCATENATE("https://",B10,".bes_ext_api:8443/",D10,MID(B10,2,15),"/",I10,""),""),"") -> https://v630.bes_ext_api:8443/dmz630/das_middleware | W10: https://172.16.150.71:8443/dmz630/das_middleware
A11: 8 | B11: v504 | C11: DMZ (TSP) & DMZ (Gov) | D11: dmz | E11: ="k8s-"&D11 -> k8s-dmz | F11: =IF(D11="dmz","trust","dmz") -> trust | G11: 31013 | H11: 32013 | I11: ecms_portal | J11: BES ECMS portal | K11: web access from TSP/Gov | O11: api | R11: web portal | S11: =IF(LEN(B11)>0,IF(ISNUMBER(FIND("api",CONCATENATE(L11,M11))),CONCATENATE("http://ltm",MID(B11,2,15),":8000/",D11,MID(B11,2,15),"/",$I11),""),"") | T11: =IF(LEN(B11)>0,IF(ISNUMBER(FIND("api",CONCATENATE(L11,M11))),CONCATENATE("https://ltm",MID(B11,2,15),":8443/",D11,MID(B11,2,15),"/",$I11),""),"") | U11: =IF(D11="dmz",IF(ISNUMBER(FIND("api",K11)),CONCATENATE("http://",B11,".bes_ext_api:8000/",D11,MID(B11,2,15),"/",I11,""),""),"") | V11: =IF(D11="dmz",IF(ISNUMBER(FIND("api",K11)),CONCATENATE("https://",B11,".bes_ext_api:8443/",D11,MID(B11,2,15),"/",I11,""),""),"")
A12: 119 | B12: v504 | C12: DMZ (TSP) & DMZ (Gov) | D12: dmz | E12: ="k8s-"&D12 -> k8s-dmz | F12: =IF(D12="dmz","trust","dmz") -> trust | G12: 31013 | H12: 32013 | I12: ecms_portal | J12: BES ECMS portal | K12: web access from TSP/Gov | O12: api | R12: web portal | S12: =IF(LEN(B12)>0,IF(ISNUMBER(FIND("api",CONCATENATE(L12,M12))),CONCATENATE("http://ltm",MID(B12,2,15),":8000/",D12,MID(B12,2,15),"/",$I12),""),"") | T12: =IF(LEN(B12)>0,IF(ISNUMBER(FIND("api",CONCATENATE(L12,M12))),CONCATENATE("https://ltm",MID(B12,2,15),":8443/",D12,MID(B12,2,15),"/",$I12),""),"") | U12: =IF(D12="dmz",IF(ISNUMBER(FIND("api",K12)),CONCATENATE("http://",B12,".bes_ext_api:8000/",D12,MID(B12,2,15),"/",I12,""),""),"") | V12: =IF(D12="dmz",IF(ISNUMBER(FIND("api",K12)),CONCATENATE("https://",B12,".bes_ext_api:8443/",D12,MID(B12,2,15),"/",I12,""),""),"")
A13: 9 | B13: v804 | C13: DMZ (Internet) | D13: dmz | E13: ="k8s-"&D13 -> k8s-dmz | F13: =IF(D13="dmz","trust","dmz") -> trust | G13: 31029 | H13: 32029 | I13: ffts_web | J13: customer web | K13: web access from Internet | M13: web socket | P13: api / web socket | R13: web portal | S13: =IF(LEN(B13)>0,IF(ISNUMBER(FIND("api",CONCATENATE(L13,M13))),CONCATENATE("http://ltm",MID(B13,2,15),":8000/",D13,MID(B13,2,15),"/",$I13),""),"") | T13: =IF(LEN(B13)>0,IF(ISNUMBER(FIND("api",CONCATENATE(L13,M13))),CONCATENATE("https://ltm",MID(B13,2,15),":8443/",D13,MID(B13,2,15),"/",$I13),""),"") | U13: =IF(D13="dmz",IF(ISNUMBER(FIND("api",K13)),CONCATENATE("http://",B13,".bes_ext_api:8000/",D13,MID(B13,2,15),"/",I13,""),""),"") | V13: =IF(D13="dmz",IF(ISNUMBER(FIND("api",K13)),CONCATENATE("https://",B13,".bes_ext_api:8443/",D13,MID(B13,2,15),"/",I13,""),""),"")
A14: 10 | B14: v504 | C14: DMZ (TSP) | D14: dmz | E14: ="k8s-"&D14 -> k8s-dmz | F14: =IF(D14="dmz","trust","dmz") -> trust | G14: 31400 | H14: 32400 | I14: notification_result | J14: notification result | K14: api call from TSP | L14: api | M14: api | N14: api call TSP Notification Middleware | O14: api | P14: api | Q14: Pulsar | R14: rest_api | S14: =IF(LEN(B14)>0,IF(ISNUMBER(FIND("api",CONCATENATE(L14,M14))),CONCATENATE("http://ltm",MID(B14,2,15),":8000/",D14,MID(B14,2,15),"/",$I14),""),"") -> http://ltm504:8000/dmz504/notification_result | T14: =IF(LEN(B14)>0,IF(ISNUMBER(FIND("api",CONCATENATE(L14,M14))),CONCATENATE("https://ltm",MID(B14,2,15),":8443/",D14,MID(B14,2,15),"/",$I14),""),"") -> https://ltm504:8443/dmz504/notification_result | U14: =IF(D14="dmz",IF(ISNUMBER(FIND("api",K14)),CONCATENATE("http://",B14,".bes_ext_api:8000/",D14,MID(B14,2,15),"/",I14,""),""),"") -> http://v504.bes_ext_api:8000/dmz504/notification_result | V14: =IF(D14="dmz",IF(ISNUMBER(FIND("api",K14)),CONCATENATE("https://",B14,".bes_ext_api:8443/",D14,MID(B14,2,15),"/",I14,""),""),"") -> https://v504.bes_ext_api:8443/dmz504/notification_result
A15: 11 | B15: v504 | C15: DMZ (TSP) | D15: dmz | E15: ="k8s-"&D15 -> k8s-dmz | F15: =IF(D15="dmz","trust","dmz") -> trust | G15: 31031 | H15: 32031 | I15: payment_middleware | J15: payment middleware | K15: api call from TSP | L15: api | M15: api | N15: api call TSP PSIS | O15: api | P15: api | R15: rest_api | S15: =IF(LEN(B15)>0,IF(ISNUMBER(FIND("api",CONCATENATE(L15,M15))),CONCATENATE("http://ltm",MID(B15,2,15),":8000/",D15,MID(B15,2,15),"/",$I15),""),"") -> http://ltm504:8000/dmz504/payment_middleware | T15: =IF(LEN(B15)>0,IF(ISNUMBER(FIND("api",CONCATENATE(L15,M15))),CONCATENATE("https://ltm",MID(B15,2,15),":8443/",D15,MID(B15,2,15),"/",$I15),""),"") -> https://ltm504:8443/dmz504/payment_middleware | U15: =IF(D15="dmz",IF(ISNUMBER(FIND("api",K15)),CONCATENATE("http://",B15,".bes_ext_api:8000/",D15,MID(B15,2,15),"/",I15,""),""),"") -> http://v504.bes_ext_api:8000/dmz504/payment_middleware | V15: =IF(D15="dmz",IF(ISNUMBER(FIND("api",K15)),CONCATENATE("https://",B15,".bes_ext_api:8443/",D15,MID(B15,2,15),"/",I15,""),""),"") -> https://v504.bes_ext_api:8443/dmz504/payment_middleware
A16: 12 | B16: v630_itoms2 | C16: DMZ (TSP) & DMZ (DAS) | D16: dmz | E16: ="toms-"&D16 -> toms-dmz | F16: =IF(D16="dmz","trust","dmz") -> trust | G16: 31002 | H16: 32002 | I16: toms_middleware | J16: toms middleware [Docker in Standalone VM] | K16: api call from DAS/BES-Internal | L16: api | M16: api | N16: api call DAS/BES-Internal | O16: api | P16: api | R16: rest_api | S16: =IF(LEN(B16)>0,IF(ISNUMBER(FIND("api",CONCATENATE(L16,M16))),CONCATENATE("http://ltm",MID(B16,2,15),":8000/",D16,MID(B16,2,15),"/",$I16),""),"") -> http://ltm630_itoms2:8000/dmz630_itoms2/toms_middleware | T16: =IF(LEN(B16)>0,IF(ISNUMBER(FIND("api",CONCATENATE(L16,M16))),CONCATENATE("https://ltm",MID(B16,2,15),":8443/",D16,MID(B16,2,15),"/",$I16),""),"") -> https://ltm630_itoms2:8443/dmz630_itoms2/toms_middleware | U16: =IF(D16="dmz",IF(ISNUMBER(FIND("api",K16)),CONCATENATE("http://",B16,".bes_ext_api:8000/",D16,MID(B16,2,15),"/",I16,""),""),"") -> http://v630_itoms2.bes_ext_api:8000/dmz630_itoms2/toms_middleware | V16: =IF(D16="dmz",IF(ISNUMBER(FIND("api",K16)),CONCATENATE("https://",B16,".bes_ext_api:8443/",D16,MID(B16,2,15),"/",I16,""),""),"") -> https://v630_itoms2.bes_ext_api:8443/dmz630_itoms2/toms_middleware | W16: https://172.16.151.121:31002
A17: 13 | B17: v504_itoms1 | C17: DMZ (TSP) | D17: dmz | E17: ="toms-"&D17 -> toms-dmz | F17: =IF(D17="dmz","trust","dmz") -> trust | G17: 31030 | H17: 32030 | I17: toms_portal | J17: TOMS web portal [Docker in Standalone VM] | K17: web access from TSP | O17: api | P17: api | R17: web portal | S17: =IF(LEN(B17)>0,IF(ISNUMBER(FIND("api",CONCATENATE(L17,M17))),CONCATENATE("http://ltm",MID(B17,2,15),":8000/",D17,MID(B17,2,15),"/",$I17),""),"") | T17: =IF(LEN(B17)>0,IF(ISNUMBER(FIND("api",CONCATENATE(L17,M17))),CONCATENATE("https://ltm",MID(B17,2,15),":8443/",D17,MID(B17,2,15),"/",$I17),""),"") | U17: =IF(D17="dmz",IF(ISNUMBER(FIND("api",K17)),CONCATENATE("http://",B17,".bes_ext_api:8000/",D17,MID(B17,2,15),"/",I17,""),""),"") | V17: =IF(D17="dmz",IF(ISNUMBER(FIND("api",K17)),CONCATENATE("https://",B17,".bes_ext_api:8443/",D17,MID(B17,2,15),"/",I17,""),""),"")
A18: 14 | B18: v504 | C18: DMZ (TSP) | D18: dmz | E18: ="k8s-"&D18 -> k8s-dmz | F18: =IF(D18="dmz","trust","dmz") -> trust | G18: 31401 | H18: 32401 | I18: tsp_middleware | J18: TSP middleware | K18: api call from TSP | L18: api | N18: api call TSP Interface | O18: api | R18: rest_api | S18: =IF(LEN(B18)>0,IF(ISNUMBER(FIND("api",CONCATENATE(L18,M18))),CONCATENATE("http://ltm",MID(B18,2,15),":8000/",D18,MID(B18,2,15),"/",$I18),""),"") -> http://ltm504:8000/dmz504/tsp_middleware | T18: =IF(LEN(B18)>0,IF(ISNUMBER(FIND("api",CONCATENATE(L18,M18))),CONCATENATE("https://ltm",MID(B18,2,15),":8443/",D18,MID(B18,2,15),"/",$I18),""),"") -> https://ltm504:8443/dmz504/tsp_middleware | U18: =IF(D18="dmz",IF(ISNUMBER(FIND("api",K18)),CONCATENATE("http://",B18,".bes_ext_api:8000/",D18,MID(B18,2,15),"/",I18,""),""),"") -> http://v504.bes_ext_api:8000/dmz504/tsp_middleware | V18: =IF(D18="dmz",IF(ISNUMBER(FIND("api",K18)),CONCATENATE("https://",B18,".bes_ext_api:8443/",D18,MID(B18,2,15),"/",I18,""),""),"") -> https://v504.bes_ext_api:8443/dmz504/tsp_middleware
A19: 15 | B19: v504 | C19: DMZ (TSP) | D19: dmz | E19: ="k8s-"&D19 -> k8s-dmz | F19: =IF(D19="dmz","trust","dmz") -> trust | G19: 31402 | H19: 32402 | I19: ttis_middleware | J19: TTIS middleware | K19: api call from TSP | L19: api | N19: api call TSP TTIS | O19: api | R19: rest_api | S19: =IF(LEN(B19)>0,IF(ISNUMBER(FIND("api",CONCATENATE(L19,M19))),CONCATENATE("http://ltm",MID(B19,2,15),":8000/",D19,MID(B19,2,15),"/",$I19),""),"") -> http://ltm504:8000/dmz504/ttis_middleware | T19: =IF(LEN(B19)>0,IF(ISNUMBER(FIND("api",CONCATENATE(L19,M19))),CONCATENATE("https://ltm",MID(B19,2,15),":8443/",D19,MID(B19,2,15),"/",$I19),""),"") -> https://ltm504:8443/dmz504/ttis_middleware | U19: =IF(D19="dmz",IF(ISNUMBER(FIND("api",K19)),CONCATENATE("http://",B19,".bes_ext_api:8000/",D19,MID(B19,2,15),"/",I19,""),""),"") -> http://v504.bes_ext_api:8000/dmz504/ttis_middleware | V19: =IF(D19="dmz",IF(ISNUMBER(FIND("api",K19)),CONCATENATE("https://",B19,".bes_ext_api:8443/",D19,MID(B19,2,15),"/",I19,""),""),"") -> https://v504.bes_ext_api:8443/dmz504/ttis_middleware
A20: 16 | B20: v904 | C20: DMZ (Gov) | D20: dmz | E20: ="k8s-"&D20 -> k8s-dmz | F20: =IF(D20="dmz","trust","dmz") -> trust | G20: 31403 | H20: 32403 | I20: validv_middleware | J20: Valid V middleware | L20: api | N20: File upload/download from VALID V web service | O20: api | R20: rest_api / worker service (corn job) | S20: =IF(LEN(B20)>0,IF(ISNUMBER(FIND("api",CONCATENATE(L20,M20))),CONCATENATE("http://ltm",MID(B20,2,15),":8000/",D20,MID(B20,2,15),"/",$I20),""),"") -> http://ltm904:8000/dmz904/validv_middleware | T20: =IF(LEN(B20)>0,IF(ISNUMBER(FIND("api",CONCATENATE(L20,M20))),CONCATENATE("https://ltm",MID(B20,2,15),":8443/",D20,MID(B20,2,15),"/",$I20),""),"") -> https://ltm904:8443/dmz904/validv_middleware | U20: =IF(D20="dmz",IF(ISNUMBER(FIND("api",K20)),CONCATENATE("http://",B20,".bes_ext_api:8000/",D20,MID(B20,2,15),"/",I20,""),""),"") | V20: =IF(D20="dmz",IF(ISNUMBER(FIND("api",K20)),CONCATENATE("https://",B20,".bes_ext_api:8443/",D20,MID(B20,2,15),"/",I20,""),""),"")
A21: 17 | B21: v904 | C21: DMZ (Gov) | D21: dmz | E21: ="k8s-"&D21 -> k8s-dmz | F21: =IF(D21="dmz","trust","dmz") -> trust | G21: 31404 | H21: 32404 | I21: vssd_middleware | J21: VSSD middleware | L21: api | N21: File upload/download from VSSD web service | O21: api | R21: rest_api | S21: =IF(LEN(B21)>0,IF(ISNUMBER(FIND("api",CONCATENATE(L21,M21))),CONCATENATE("http://ltm",MID(B21,2,15),":8000/",D21,MID(B21,2,15),"/",$I21),""),"") -> http://ltm904:8000/dmz904/vssd_middleware | T21: =IF(LEN(B21)>0,IF(ISNUMBER(FIND("api",CONCATENATE(L21,M21))),CONCATENATE("https://ltm",MID(B21,2,15),":8443/",D21,MID(B21,2,15),"/",$I21),""),"") -> https://ltm904:8443/dmz904/vssd_middleware | U21: =IF(D21="dmz",IF(ISNUMBER(FIND("api",K21)),CONCATENATE("http://",B21,".bes_ext_api:8000/",D21,MID(B21,2,15),"/",I21,""),""),"") | V21: =IF(D21="dmz",IF(ISNUMBER(FIND("api",K21)),CONCATENATE("https://",B21,".bes_ext_api:8443/",D21,MID(B21,2,15),"/",I21,""),""),"")
A22: 18 | B22: v510 | C22: Internal Application Zone | D22: trust | E22: ="k8s-"&D22 -> k8s-trust | F22: =IF(D22="dmz","trust","dmz") -> dmz | G22: 31009 | H22: 32009 | I22: accmgt_api | J22: API for core portal management | L22: api | M22: api | O22: api | P22: api | R22: rest_api | S22: =IF(LEN(B22)>0,IF(ISNUMBER(FIND("api",CONCATENATE(L22,M22))),CONCATENATE("http://ltm",MID(B22,2,15),":8000/",D22,MID(B22,2,15),"/",$I22),""),"") -> http://ltm510:8000/trust510/accmgt_api | T22: =IF(LEN(B22)>0,IF(ISNUMBER(FIND("api",CONCATENATE(L22,M22))),CONCATENATE("https://ltm",MID(B22,2,15),":8443/",D22,MID(B22,2,15),"/",$I22),""),"") -> https://ltm510:8443/trust510/accmgt_api
A23: 19 | B23: v510 | C23: Internal Application Zone | D23: trust | E23: ="k8s-"&D23 -> k8s-trust | F23: =IF(D23="dmz","trust","dmz") -> dmz | G23: 31000 | H23: 32000 | I23: auth_api | J23: login for internal portal | L23: api | M23: api | O23: api | P23: api | R23: rest_api | S23: =IF(LEN(B23)>0,IF(ISNUMBER(FIND("api",CONCATENATE(L23,M23))),CONCATENATE("http://ltm",MID(B23,2,15),":8000/",D23,MID(B23,2,15),"/",$I23),""),"") -> http://ltm510:8000/trust510/auth_api | T23: =IF(LEN(B23)>0,IF(ISNUMBER(FIND("api",CONCATENATE(L23,M23))),CONCATENATE("https://ltm",MID(B23,2,15),":8443/",D23,MID(B23,2,15),"/",$I23),""),"") -> https://ltm510:8443/trust510/auth_api
A24: 20 | B24: v510 | C24: Internal Application Zone | D24: trust | E24: ="k8s-"&D24 -> k8s-trust | F24: =IF(D24="dmz","trust","dmz") -> dmz | G24: 31201 | H24: 32201 | I24: bes_acc_im001_fft_account_registration | J24: API for Account mangement functions | L24: api | M24: api | O24: api | P24: api | R24: rest_api | S24: =IF(LEN(B24)>0,IF(ISNUMBER(FIND("api",CONCATENATE(L24,M24))),CONCATENATE("http://ltm",MID(B24,2,15),":8000/",D24,MID(B24,2,15),"/",$I24),""),"") -> http://ltm510:8000/trust510/bes_acc_im001_fft_account_registration | T24: =IF(LEN(B24)>0,IF(ISNUMBER(FIND("api",CONCATENATE(L24,M24))),CONCATENATE("https://ltm",MID(B24,2,15),":8443/",D24,MID(B24,2,15),"/",$I24),""),"") -> https://ltm510:8443/trust510/bes_acc_im001_fft_account_registration
A25: 21 | B25: v810 | C25: External Application Zone | D25: trust | E25: ="k8s-"&D25 -> k8s-trust | F25: =IF(D25="dmz","trust","dmz") -> dmz | G25: 31201 | H25: 32201 | I25: bes_acc_im001_fft_account_registration | J25: API for Account mangement functions | L25: api | M25: api | O25: api | P25: api | R25: rest_api | S25: =IF(LEN(B25)>0,IF(ISNUMBER(FIND("api",CONCATENATE(L25,M25))),CONCATENATE("http://ltm",MID(B25,2,15),":8000/",D25,MID(B25,2,15),"/",$I25),""),"") -> http://ltm810:8000/trust810/bes_acc_im001_fft_account_registration | T25: =IF(LEN(B25)>0,IF(ISNUMBER(FIND("api",CONCATENATE(L25,M25))),CONCATENATE("https://ltm",MID(B25,2,15),":8443/",D25,MID(B25,2,15),"/",$I25),""),"") -> https://ltm810:8443/trust810/bes_acc_im001_fft_account_registration
A26: 22 | B26: v510 | C26: Internal Application Zone | D26: trust | E26: ="k8s-"&D26 -> k8s-trust | F26: =IF(D26="dmz","trust","dmz") -> dmz | G26: 31202 | H26: 32202 | I26: bes_acc_im002_fft_vehicle_management | J26: API for Account mangement functions | L26: api | M26: api | O26: api | P26: api | R26: rest_api | S26: =IF(LEN(B26)>0,IF(ISNUMBER(FIND("api",CONCATENATE(L26,M26))),CONCATENATE("http://ltm",MID(B26,2,15),":8000/",D26,MID(B26,2,15),"/",$I26),""),"") -> http://ltm510:8000/trust510/bes_acc_im002_fft_vehicle_management | T26: =IF(LEN(B26)>0,IF(ISNUMBER(FIND("api",CONCATENATE(L26,M26))),CONCATENATE("https://ltm",MID(B26,2,15),":8443/",D26,MID(B26,2,15),"/",$I26),""),"") -> https://ltm510:8443/trust510/bes_acc_im002_fft_vehicle_management
A27: 23 | B27: v810 | C27: External Application Zone | D27: trust | E27: ="k8s-"&D27 -> k8s-trust | F27: =IF(D27="dmz","trust","dmz") -> dmz | G27: 31202 | H27: 32202 | I27: bes_acc_im002_fft_vehicle_management | J27: API for Account mangement functions | L27: api | M27: api | O27: api | P27: api | R27: rest_api | S27: =IF(LEN(B27)>0,IF(ISNUMBER(FIND("api",CONCATENATE(L27,M27))),CONCATENATE("http://ltm",MID(B27,2,15),":8000/",D27,MID(B27,2,15),"/",$I27),""),"") -> http://ltm810:8000/trust810/bes_acc_im002_fft_vehicle_management | T27: =IF(LEN(B27)>0,IF(ISNUMBER(FIND("api",CONCATENATE(L27,M27))),CONCATENATE("https://ltm",MID(B27,2,15),":8443/",D27,MID(B27,2,15),"/",$I27),""),"") -> https://ltm810:8443/trust810/bes_acc_im002_fft_vehicle_management
A28: 24 | B28: v510 | C28: Internal Application Zone | D28: trust | E28: ="k8s-"&D28 -> k8s-trust | F28: =IF(D28="dmz","trust","dmz") -> dmz | G28: 31203 | H28: 32203 | I28: bes_acc_im003_fft_vehicle_group_management | J28: API for Account mangement functions | L28: api | M28: api | O28: api | P28: api | R28: rest_api | S28: =IF(LEN(B28)>0,IF(ISNUMBER(FIND("api",CONCATENATE(L28,M28))),CONCATENATE("http://ltm",MID(B28,2,15),":8000/",D28,MID(B28,2,15),"/",$I28),""),"") -> http://ltm510:8000/trust510/bes_acc_im003_fft_vehicle_group_management | T28: =IF(LEN(B28)>0,IF(ISNUMBER(FIND("api",CONCATENATE(L28,M28))),CONCATENATE("https://ltm",MID(B28,2,15),":8443/",D28,MID(B28,2,15),"/",$I28),""),"") -> https://ltm510:8443/trust510/bes_acc_im003_fft_vehicle_group_management
A29: 25 | B29: v810 | C29: External Application Zone | D29: trust | E29: ="k8s-"&D29 -> k8s-trust | F29: =IF(D29="dmz","trust","dmz") -> dmz | G29: 31203 | H29: 32203 | I29: bes_acc_im003_fft_vehicle_group_management | J29: API for Account mangement functions | L29: api | M29: api | O29: api | P29: api | R29: rest_api | S29: =IF(LEN(B29)>0,IF(ISNUMBER(FIND("api",CONCATENATE(L29,M29))),CONCATENATE("http://ltm",MID(B29,2,15),":8000/",D29,MID(B29,2,15),"/",$I29),""),"") -> http://ltm810:8000/trust810/bes_acc_im003_fft_vehicle_group_management | T29: =IF(LEN(B29)>0,IF(ISNUMBER(FIND("api",CONCATENATE(L29,M29))),CONCATENATE("https://ltm",MID(B29,2,15),":8443/",D29,MID(B29,2,15),"/",$I29),""),"") -> https://ltm810:8443/trust810/bes_acc_im003_fft_vehicle_group_management
A30: 26 | B30: v510 | C30: Internal Application Zone | D30: trust | E30: ="k8s-"&D30 -> k8s-trust | F30: =IF(D30="dmz","trust","dmz") -> dmz | G30: 31204 | H30: 32204 | I30: bes_acc_im004_fft_account_search | J30: API for Account mangement functions | L30: api | M30: api | O30: api | P30: api | R30: rest_api | S30: =IF(LEN(B30)>0,IF(ISNUMBER(FIND("api",CONCATENATE(L30,M30))),CONCATENATE("http://ltm",MID(B30,2,15),":8000/",D30,MID(B30,2,15),"/",$I30),""),"") -> http://ltm510:8000/trust510/bes_acc_im004_fft_account_search | T30: =IF(LEN(B30)>0,IF(ISNUMBER(FIND("api",CONCATENATE(L30,M30))),CONCATENATE("https://ltm",MID(B30,2,15),":8443/",D30,MID(B30,2,15),"/",$I30),""),"") -> https://ltm510:8443/trust510/bes_acc_im004_fft_account_search
A31: 27 | B31: v810 | C31: External Application Zone | D31: trust | E31: ="k8s-"&D31 -> k8s-trust | F31: =IF(D31="dmz","trust","dmz") -> dmz | G31: 31204 | H31: 32204 | I31: bes_acc_im004_fft_account_search | J31: API for Account mangement functions | L31: api | M31: api | O31: api | P31: api | R31: rest_api | S31: =IF(LEN(B31)>0,IF(ISNUMBER(FIND("api",CONCATENATE(L31,M31))),CONCATENATE("http://ltm",MID(B31,2,15),":8000/",D31,MID(B31,2,15),"/",$I31),""),"") -> http://ltm810:8000/trust810/bes_acc_im004_fft_account_search | T31: =IF(LEN(B31)>0,IF(ISNUMBER(FIND("api",CONCATENATE(L31,M31))),CONCATENATE("https://ltm",MID(B31,2,15),":8443/",D31,MID(B31,2,15),"/",$I31),""),"") -> https://ltm810:8443/trust810/bes_acc_im004_fft_account_search
A32: 28 | B32: v510 | C32: Internal Application Zone | D32: trust | E32: ="k8s-"&D32 -> k8s-trust | F32: =IF(D32="dmz","trust","dmz") -> dmz | G32: 31205 | H32: 32205 | I32: bes_acc_im005_fft_driver_approval | J32: API for Account mangement functions | L32: api | M32: api | O32: api | P32: api | R32: rest_api | S32: =IF(LEN(B32)>0,IF(ISNUMBER(FIND("api",CONCATENATE(L32,M32))),CONCATENATE("http://ltm",MID(B32,2,15),":8000/",D32,MID(B32,2,15),"/",$I32),""),"") -> http://ltm510:8000/trust510/bes_acc_im005_fft_driver_approval | T32: =IF(LEN(B32)>0,IF(ISNUMBER(FIND("api",CONCATENATE(L32,M32))),CONCATENATE("https://ltm",MID(B32,2,15),":8443/",D32,MID(B32,2,15),"/",$I32),""),"") -> https://ltm510:8443/trust510/bes_acc_im005_fft_driver_approval
A33: 29 | B33: v810 | C33: External Application Zone | D33: trust | E33: ="k8s-"&D33 -> k8s-trust | F33: =IF(D33="dmz","trust","dmz") -> dmz | G33: 31205 | H33: 32205 | I33: bes_acc_im005_fft_driver_approval | J33: API for Account mangement functions | L33: api | M33: api | O33: api | P33: api | R33: rest_api | S33: =IF(LEN(B33)>0,IF(ISNUMBER(FIND("api",CONCATENATE(L33,M33))),CONCATENATE("http://ltm",MID(B33,2,15),":8000/",D33,MID(B33,2,15),"/",$I33),""),"") -> http://ltm810:8000/trust810/bes_acc_im005_fft_driver_approval | T33: =IF(LEN(B33)>0,IF(ISNUMBER(FIND("api",CONCATENATE(L33,M33))),CONCATENATE("https://ltm",MID(B33,2,15),":8443/",D33,MID(B33,2,15),"/",$I33),""),"") -> https://ltm810:8443/trust810/bes_acc_im005_fft_driver_approval
... A56: 46 | B56: v810 | C56: External Application Zone | D56: trust | E56: ="k8s-"&D56 -> k8s-trust | F56: =IF(D56="dmz","trust","dmz") -> dmz | G56: 31307 | H56: 32307 | I56: bes_cre_im007_notification_template_management | J56: API for notification management | L56: api | M56: api | O56: api | P56: api | R56: rest_api | S56: =IF(LEN(B56)>0,IF(ISNUMBER(FIND("api",CONCATENATE(L56,M56))),CONCATENATE("http://ltm",MID(B56,2,15),":8000/",D56,MID(B56,2,15),"/",$I56),""),"") -> http://ltm810:8000/trust810/bes_cre_im007_notification_template_management | T56: =IF(LEN(B56)>0,IF(ISNUMBER(FIND("api",CONCATENATE(L56,M56))),CONCATENATE("https://ltm",MID(B56,2,15),":8443/",D56,MID(B56,2,15),"/",$I56),""),"") -> https://ltm810:8443/trust810/bes_cre_im007_notification_template_management
A57: 47 | B57: v510 | C57: Internal Application Zone | D57: trust | E57: ="k8s-"&D57 -> k8s-trust | F57: =IF(D57="dmz","trust","dmz") -> dmz | G57: 31308 | H57: 32308 | I57: bes_cre_im008_notification_message_management | J57: API for notification management | L57: api | M57: api | O57: api | P57: api | Q57: Pulsar | R57: rest_api | S57: =IF(LEN(B57)>0,IF(ISNUMBER(FIND("api",CONCATENATE(L57,M57))),CONCATENATE("http://ltm",MID(B57,2,15),":8000/",D57,MID(B57,2,15),"/",$I57),""),"") -> http://ltm510:8000/trust510/bes_cre_im008_notification_message_management | T57: =IF(LEN(B57)>0,IF(ISNUMBER(FIND("api",CONCATENATE(L57,M57))),CONCATENATE("https://ltm",MID(B57,2,15),":8443/",D57,MID(B57,2,15),"/",$I57),""),"") -> https://ltm510:8443/trust510/bes_cre_im008_notification_message_management
A58: 48 | B58: v810 | C58: External Application Zone | D58: trust | E58: ="k8s-"&D58 -> k8s-trust | F58: =IF(D58="dmz","trust","dmz") -> dmz | G58: 31308 | H58: 32308 | I58: bes_cre_im008_notification_message_management | J58: API for notification management | L58: api | M58: api | O58: api | P58: api | Q58: Pulsar | R58: rest_api | S58: =IF(LEN(B58)>0,IF(ISNUMBER(FIND("api",CONCATENATE(L58,M58))),CONCATENATE("http://ltm",MID(B58,2,15),":8000/",D58,MID(B58,2,15),"/",$I58),""),"") -> http://ltm810:8000/trust810/bes_cre_im008_notification_message_management | T58: =IF(LEN(B58)>0,IF(ISNUMBER(FIND("api",CONCATENATE(L58,M58))),CONCATENATE("https://ltm",MID(B58,2,15),":8443/",D58,MID(B58,2,15),"/",$I58),""),"") -> https://ltm810:8443/trust810/bes_cre_im008_notification_message_management
A59: 49 | B59: v510 | C59: Internal Application Zone | D59: trust | E59: ="k8s-"&D59 -> k8s-trust | F59: =IF(D59="dmz","trust","dmz") -> dmz | G59: 31309 | H59: 32309 | I59: bes_cre_im009_notification_processor | J59: app for notification | L59: api | M59: api | O59: api | P59: api | Q59: Pulsar | R59: rest_api | S59: =IF(LEN(B59)>0,IF(ISNUMBER(FIND("api",CONCATENATE(L59,M59))),CONCATENATE("http://ltm",MID(B59,2,15),":8000/",D59,MID(B59,2,15),"/",$I59),""),"") -> http://ltm510:8000/trust510/bes_cre_im009_notification_processor | T59: =IF(LEN(B59)>0,IF(ISNUMBER(FIND("api",CONCATENATE(L59,M59))),CONCATENATE("https://ltm",MID(B59,2,15),":8443/",D59,MID(B59,2,15),"/",$I59),""),"") -> https://ltm510:8443/trust510/bes_cre_im009_notification_processor
A60: 50 | B60: v810 | C60: External Application Zone | D60: trust | E60: ="k8s-"&D60 -> k8s-trust | F60: =IF(D60="dmz","trust","dmz") -> dmz | G60: 31309 | H60: 32309 | I60: bes_cre_im009_notification_processor | J60: app for notification | L60: api | M60: api | O60: api | P60: api | Q60: Pulsar | R60: rest_api | S60: =IF(LEN(B60)>0,IF(ISNUMBER(FIND("api",CONCATENATE(L60,M60))),CONCATENATE("http://ltm",MID(B60,2,15),":8000/",D60,MID(B60,2,15),"/",$I60),""),"") -> http://ltm810:8000/trust810/bes_cre_im009_notification_processor | T60: =IF(LEN(B60)>0,IF(ISNUMBER(FIND("api",CONCATENATE(L60,M60))),CONCATENATE("https://ltm",MID(B60,2,15),":8443/",D60,MID(B60,2,15),"/",$I60),""),"") -> https://ltm810:8443/trust810/bes_cre_im009_notification_processor
A61: 51 | B61: v510 | C61: Internal Application Zone | D61: trust | E61: ="k8s-"&D61 -> k8s-trust | F61: =IF(D61="dmz","trust","dmz") -> dmz | G61: 31310 | H61: 32310 | I61: bes_cre_im010_shortlink | J61: API for core functions | L61: api | M61: api | O61: api | P61: api | R61: rest_api | S61: =IF(LEN(B61)>0,IF(ISNUMBER(FIND("api",CONCATENATE(L61,M61))),CONCATENATE("http://ltm",MID(B61,2,15),":8000/",D61,MID(B61,2,15),"/",$I61),""),"") -> http://ltm510:8000/trust510/bes_cre_im010_shortlink | T61: =IF(LEN(B61)>0,IF(ISNUMBER(FIND("api",CONCATENATE(L61,M61))),CONCATENATE("https://ltm",MID(B61,2,15),":8443/",D61,MID(B61,2,15),"/",$I61),""),"") -> https://ltm510:8443/trust510/bes_cre_im010_shortlink
A62: 52 | B62: v810 | C62: External Application Zone | D62: trust | E62: ="k8s-"&D62 -> k8s-trust | F62: =IF(D62="dmz","trust","dmz") -> dmz | G62: 31310 | H62: 32310 | I62: bes_cre_im010_shortlink | J62: API for core functions | L62: api | M62: api | O62: api | P62: api | R62: rest_api | S62: =IF(LEN(B62)>0,IF(ISNUMBER(FIND("api",CONCATENATE(L62,M62))),CONCATENATE("http://ltm",MID(B62,2,15),":8000/",D62,MID(B62,2,15),"/",$I62),""),"") -> http://ltm810:8000/trust810/bes_cre_im010_shortlink | T62: =IF(LEN(B62)>0,IF(ISNUMBER(FIND("api",CONCATENATE(L62,M62))),CONCATENATE("https://ltm",MID(B62,2,15),":8443/",D62,MID(B62,2,15),"/",$I62),""),"") -> https://ltm810:8443/trust810/bes_cre_im010_shortlink
...

Sheet svc_access_mapping
D1: Source(outbound)
D2: ccs_middleware | E2: bes_wmm | F2: ffts_web | G2: payment_middleware | H2: bescore_portal | I2: bes_signalr_server | J2: ecms_portal | K2: ccms_portal | L2: toms_middleware | M2: toms_portal | N2: toms_api | O2: toms_auth_api | P2: das_middleware | Q2: auth_api | R2: accmgt_api | S2: ecms_api | T2: central_db_services_accmgt | U2: central_db_services_core | V2: central_db_services_ccms | W2: central_db_services_ecms | X2: das_video | Y2: tx_validation | Z2: notification_middleware | AA2: tsp_middleware | AB2: secondocr_webapi | AC2: ccms_api | AD2: bes_acc_im001_fft_account_registration | AE2: bes_acc_im002_fft_vehicle_management | AF2: bes_acc_im003_fft_vehicle_group_management | AG2: bes_acc_im004_fft_account_search | AH2: bes_acc_im005_fft_driver_approval | AI2: bes_acc_im006_fft_account_management | AJ2: bes_acc_im007_fft_vehicle_pairing | AK2: bes_acc_im008_fft_tag_management | AL2: bes_acc_im009_fft_payment_and_billing | AM2: bes_acc_im010_fft_transaction | AN2: bes_cre_im001_tokenization | AO2: bes_cre_im002_otp | AP2: bes_cre_im007_notification_template_management | AQ2: bes_cre_im008_notification_message_management | AR2: bes_cre_im009_notification_processor | AS2: bes_cre_im010_shortlink | AT2: ttis_middleware | AU2: valid_v_middleware | AV2: vssd_middleware | AW2: bes_ccs | AX2: bes_das_im001_general | AY2: bes_tsp_misc | AZ2: bes_ttis | BA2: bes_valid_v | BB2: bes_vssd | BC2: conf_setting | BD2: das_data_consumer | BE2: das_evidence_record_consumer | BF2: das_transaction_record_consumer | BG2: statement_api | BH2: toll_cal_setting | BI2: external - Valid V | BJ2: external - CCS | BK2: external - DAS | BL2: external - Internet | BM2: external - Government | BN2: external - TSP | BO2: external - VSSD
A3: vLan | B3: destination(inbound) | C3: Port | D3: v904 | E3: v504 / v804 | F3: v804 | G3: v504 | H3: v504 / v904 | I3: v504 | J3: v504 / v904 | K3: v504 / v904 | L3: v504 / v630 | M3: v504 | N3: v511 | O3: v511 | P3: v630 | Q3: v510 | R3: v510 | S3: v510 | T3: v510 | U3: v510/v810 | V3: v510 | W3: v510 | X3: v630 | Y3: v510 | Z3: v504 | AA3: v504 | AB3: v510 | AC3: v510 | AD3: v510/v810 | AE3: v510/v810 | AF3: v510/v810 | AG3: v510/v810 | AH3: v510/v810 | AI3: v510/v810 | AJ3: v510/v810 | AK3: v510/v810 | AL3: v510/v810 | AM3: v510/v810 | AN3: v510/v810 | AO3: v510/v810 | AP3: v510/v810 | AQ3: v510/v810 | AR3: v510/v810 | AS3: v510/v810 | AT3: v504 | AU3: v904 | AV3: v904 | AW3: v510 | AX3: v510 | AY3: v510 | AZ3: v510 | BA3: v510 | BB3: v510 | BC3: v510 | BD3: v510 | BE3: v510 | BF3: v510 | BG3: v810 | BH3: v510
A4: v904 | B4: ccs_middleware | C4: 31211 | AW4: ü
A5: v504 / v804 | B5: bes_wmm | C5: 31026 | F5: ü | BL5: ü | BN5: ü
A6: v804 | B6: ffts_web | C6: 31029 | BL6: ü
A7: v504 | B7: payment_middleware | C7: 31031 | L7: ü | AI7: ü | AL7: ü | BN7: ü
A8: v504 / v904 | B8: bescore_portal | C8: 31010 | I8: ü | BM8: ü | BN8: ü
A9: v504 | B9: bes_signalr_server | C9: 31011 | H9: ü | J9: ü | K9: ü | R9: ü | S9: ü | AC9: ü | BN9: ü
A10: v504 / v904 | B10: ecms_portal | C10: 31013 | I10: ü | BM10: ü | BN10: ü
A11: v504 / v904 | B11: ccms_portal | C11: 31028 | I11: ü | BM11: ü | BN11: ü
A12: v??? / v630 | B12: toms_middleware | C12: 31030 | G12: ü | N12: ü | P12: ü | X12: ü | Z12: ü | AA12: ü | AT12: ü | BK12: ü
A13: v??? | B13: toms_portal | C13: 31002 | BN13: ü
A14: v511 | B14: toms_api | C14: 31001 | L14: ü | M14: ü
A15: v511 | B15: toms_auth_api | C15: 31004 | M15: ü
A16: v630 | B16: das_middleware | C16: 31025 | L16: ü | AX16: ü | BK16: ü
A17: v510 | B17: auth_api | C17: 31000 | H17: ü | J17: ü | K17: ü
A18: v510 | B18: accmgt_api | C18: 31009 | E18: ü | H18: ü | J18: ü | K18: ü | S18: ü | AC18: ü | AD18: ü | AE18: ü | AF18: ü | AG18: ü | AH18: ü | AI18: ü | AJ18: ü | AK18: ü | AL18: ü | AM18: ü | AN18: ü | AO18: ü | AS18: ü | AY18: ü | AZ18: ü | BA18: ü
A19: v510 | B19: ecms_api | C19: 31014 | H19: ü | J19: ü | R19: ü | AC19: ü | AD19: ü | AE19: ü | AF19: ü | AG19: ü | AH19: ü | AI19: ü | AJ19: ü | AK19: ü | AL19: ü | AM19: ü | AN19: ü | AO19: ü | AS19: ü
A20: v510 | B20: central_db_services_accmgt | C20: 31015 | R20: ü | S20: ü | Y20: ü | AC20: ü | AD20: ü | AE20: ü | AF20: ü | AG20: ü | AH20: ü | AI20: ü | AJ20: ü | AK20: ü | AL20: ü | AM20: ü | AY20: ü | BC20: ü
A21: v510/v810 | B21: central_db_services_core | C21: 31016 | R21: ü | S21: ü | Y21: ü | AC21: ü | AD21: ü | AE21: ü | AF21: ü | AG21: ü | AH21: ü | AI21: ü | AJ21: ü | AK21: ü | AL21: ü | AM21: ü | AN21: ü | AO21: ü | AP21: ü | AQ21: ü | AR21: ü | AS21: ü | AW21: ü | AX21: ü | AY21: ü | AZ21: ü | BA21: ü | BB21: ü | BC21: ü | BD21: ü | BE21: ü | BF21: ü | BG21: ü | BH21: ü
A22: v510 | B22: central_db_services_ccms | C22: 31017 | R22: ü | AC22: ü | BC22: ü
A23: v510 | B23: central_db_services_ecms | C23: 31018 | R23: ü | S23: ü | BC23: ü
A24: v603 | B24: das_video | C24: 31019 | L24: ü | AX24: ü | BK24: ü
A25: v510 | B25: tx_validation | C25: 31021 | S25: ü | AB25: ü | BD25: ü | BE25: ü | BF25: ü
A26: v504 | B26: notification_middleware | C26: 31400 | L26: ü | BN26: ü
A27: v504 | B27: tsp_middleware | C27: 31401 | L27: ü | BN27: ü
A28: v510 | B28: secondocr_webapi | C28: 31024 | Y28: ü
A29: v510 | B29: ccms_api | C29: 31027 | E29: ü | H29: ü | J29: ü | K29: ü | R29: ü | S29: ü | AD29: ü | AE29: ü | AF29: ü | AG29: ü | AH29: ü | AI29: ü | AJ29: ü | AK29: ü | AL29: ü | AM29: ü | AN29: ü | AO29: ü | AS29: ü
A30: v510/v810 | B30: bes_acc_im001_fft_account_registration | C30: 31201 | E30: ü | H30: ü | K30: ü | R30: ü | AC30: ü | AE30: ü | AF30: ü | AG30: ü | AH30: ü | AI30: ü | AJ30: ü | AK30: ü | AL30: ü | AM30: ü | AN30: ü | AO30: ü | AS30: ü
A31: v510/v810 | B31: bes_acc_im002_fft_vehicle_management | C31: 31202 | E31: ü | H31: ü | K31: ü | R31: ü | AC31: ü | AD31: ü | AF31: ü | AG31: ü | AH31: ü | AI31: ü | AJ31: ü | AK31: ü | AL31: ü | AM31: ü | AN31: ü | AO31: ü | AS31: ü | AZ31: ü | BA31: ü
A32: v510/v810 | B32: bes_acc_im003_fft_vehicle_group_management | C32: 31203 | E32: ü | H32: ü | K32: ü | R32: ü | AC32: ü | AD32: ü | AE32: ü | AG32: ü | AH32: ü | AI32: ü | AJ32: ü | AK32: ü | AL32: ü | AM32: ü | AN32: ü | AO32: ü | AS32: ü
A33: v510/v810 | B33: bes_acc_im004_fft_account_search | C33: 31204 | E33: ü | H33: ü | K33: ü | R33: ü | AC33: ü | AD33: ü | AE33: ü | AF33: ü | AH33: ü | AI33: ü | AJ33: ü | AK33: ü | AL33: ü | AM33: ü | AN33: ü | AO33: ü | AS33: ü
A34: v510/v810 | B34: bes_acc_im005_fft_driver_approval | C34: 31205 | E34: ü | H34: ü | K34: ü | R34: ü | AC34: ü | AD34: ü | AE34: ü | AF34: ü | AG34: ü | AI34: ü | AJ34: ü | AK34: ü | AL34: ü | AM34: ü | AN34: ü | AO34: ü | AS34: ü
A35: v510/v810 | B35: bes_acc_im006_fft_account_management | C35: 31206 | E35: ü | G35: ü | H35: ü | K35: ü | R35: ü | AC35: ü | AD35: ü | AE35: ü | AF35: ü | AG35: ü | AH35: ü | AJ35: ü | AK35: ü | AL35: ü | AM35: ü | AN35: ü | AO35: ü | AR35: ü | AS35: ü | AY35: ü
A36: v510/v810 | B36: bes_acc_im007_fft_vehicle_pairing | C36: 31207 | E36: ü | H36: ü | K36: ü | R36: ü | AC36: ü | AD36: ü | AE36: ü | AF36: ü | AG36: ü | AH36: ü | AI36: ü | AK36: ü | AL36: ü | AM36: ü | AN36: ü | AO36: ü | AS36: ü
A37: v510/v810 | B37: bes_acc_im008_fft_tag_management | C37: 31208 | E37: ü | H37: ü | K37: ü | R37: ü | AC37: ü | AD37: ü | AE37: ü | AF37: ü | AG37: ü | AH37: ü | AI37: ü | AJ37: ü | AL37: ü | AM37: ü | AN37: ü | AO37: ü | AS37: ü | AZ37: ü | BA37: ü
A38: v510/v810 | B38: bes_acc_im009_fft_payment_and_billing | C38: 31209 | E38: ü | G38: ü | H38: ü | K38: ü | R38: ü | Y38: ü | AC38: ü | AD38: ü | AE38: ü | AF38: ü | AG38: ü | AH38: ü | AI38: ü | AJ38: ü | AK38: ü | AM38: ü | AN38: ü | AO38: ü | AS38: ü
A39: v510/v810 | B39: bes_acc_im010_fft_transaction | C39: 31210 | E39: ü | H39: ü | K39: ü | R39: ü | AC39: ü | AD39: ü | AE39: ü | AF39: ü | AG39: ü | AH39: ü | AI39: ü | AJ39: ü | AK39: ü | AL39: ü | AN39: ü | AO39: ü | AS39: ü
A40: v510/v810 | B40: bes_cre_im001_tokenization | C40: 31301 | R40: ü | S40: ü | AC40: ü | AD40: ü | AE40: ü | AF40: ü | AG40: ü | AH40: ü | AI40: ü | AJ40: ü | AK40: ü | AL40: ü | AM40: ü | AO40: ü | AR40: ü
...

Sheet kong_np_var
I1: put upstream cmd | J1: curl -X PUT <kong_api_url>/upstreams/<upstream_name>
I2: put service cmd | J2: curl -X PUT <kong_api_url>/services/<service_name> -H "Content-Type: application/json" -d '{"protocol":"http","host":"<upstream_name>","port":<port>}'
I3: put route cmd | J3: curl -X PUT <kong_api_url>/services/<service_name>/routes/<route_name> -H "Content-Type: application/json" -d '{"protocols":["http"],"hosts":["<host>"],"paths":["<path>"]}'
I4: create target cmd | J4: curl -X POST <kong_api_url>/upstreams/<upstream_id>/targets -d "target=<target>"
A6: kong_api_url | B6: trust | C6: http://172.24.148.160:8001
A7: kong_api_url | B7: dmz | C7: http://172.24.149.80:8001
C9: source_vlan
A10: kong lb ip | B10: v510 | C10: v504 | D10: 172.24.149.183
A11: kong lb ip | B11: v810 | C11: v804 | D11: 172.24.149.151
A12: kong lb ip | B12: v910 | C12: v904 | D12: 172.24.149.167
A13: kong lb ip | B13: v804 | C13: v810 | D13: 172.24.151.71
A14: kong lb ip | B14: v904 | C14: v910 | D14: 172.24.150.39
A15: kong lb ip | B15: v504 | C15: v510 | D15: 172.24.148.71
A16: kong lb ip | B16: v630 | C16: v510 | D16: 172.24.150.71
B19: vlan | C19: worker_1 | D19: worker_2 | E19: worker_3 | F19: worker_4 | G19: worker_5 | H19: worker_6
A20: k8s lb ip | B20: v510 | C20: 172.24.148.131 | D20: 172.24.148.132 | E20: 172.24.148.133 | F20: 172.24.148.134 | G20: 172.24.148.135 | H20: 172.24.148.136
A21: k8s lb ip | B21: v810 | C21: 172.24.148.195 | D21: 172.24.148.196 | E21: 172.24.148.197 | F21: 172.24.148.198 | G21: 172.24.148.199 | H21: 172.24.148.200
A22: k8s lb ip | B22: v910 | C22: 172.24.151.3 | D22: 172.24.151.4 | E22: 172.24.151.5 | F22: 172.24.151.6 | G22: 172.24.151.7 | H22: 172.24.151.8
A23: k8s lb ip | B23: v804 | C23: 172.24.149.70 | D23: 172.24.149.71 | E23: 172.24.149.72
A24: k8s lb ip | B24: v904 | C24: 172.24.149.102 | D24: 172.24.149.103 | E24: 172.24.149.104
A25: k8s lb ip | B25: v504 | C25: 172.24.148.102 | D25: 172.24.148.103 | E25: 172.24.148.104
A26: k8s lb ip | B26: v630 | C26: 172.24.151.109 | D26: 172.24.151.110 | E26: 172.24.151.111

Sheet kong_np_script
A1: is_rest_api | C1: zone | D1: vlan | E1: port | F1: upstream_name | G1: service_name | H1: route_name | I1: target_1 | J1: target_2 | K1: target_3 | L1: target_4 | M1: target_5 | N1: target_6 | O1: kong_host | P1: path | Q1: kong_api_url | R1: upstream_curl | S1: service_curl | T1: route_curl | U1: target_1_curl | V1: target_2_curl | W1: target_3_curl | X1: target_4_curl | Y1: target_5_curl | Z1: target_6_curl
A2: =IF(ISNUMBER(SEARCH("rest_api",svc!R2)),1,0) -> 1 | C2: =svc!D2 -> dmz | D2: =svc!$B2 -> v504 | E2: =svc!G2 -> 31011 | F2: =CONCATENATE("ups-",svc!$B2,"-",svc!I2) -> ups-v504-bes_signalr_server | G2: =CONCATENATE("svc-",svc!$B2,"-",svc!I2) -> svc-v504-bes_signalr_server | H2: =CONCATENATE("route-",VLOOKUP($D2,kong_np_var!$B$10:$D$16,2,FALSE),"-",svc!$B2,"-",svc!I2) -> route-v510-v504-bes_signalr_server | I2: =CONCATENATE(VLOOKUP($D2,kong_np_var!$B$20:$H$26,SUBSTITUTE(I$1,"target_","") + 1,FALSE),":",$E2) -> 172.24.148.102:31011 | J2: =CONCATENATE(VLOOKUP($D2,kong_np_var!$B$20:$H$26,SUBSTITUTE(J$1,"target_","") + 1,FALSE),":",$E2) -> 172.24.148.103:31011 | K2: =CONCATENATE(VLOOKUP($D2,kong_np_var!$B$20:$H$26,SUBSTITUTE(K$1,"target_","") + 1,FALSE),":",$E2) -> 172.24.148.104:31011 | L2: =IF($C2="dmz","",CONCATENATE(VLOOKUP($D2,kong_np_var!$B$20:$H$26,SUBSTITUTE(L$1,"target_","") + 1,FALSE),":",$E2)) | M2: =IF($C2="dmz","",CONCATENATE(VLOOKUP($D2,kong_np_var!$B$20:$H$26,SUBSTITUTE(M$1,"target_","") + 1,FALSE),":",$E2)) | N2: =IF($C2="dmz","",CONCATENATE(VLOOKUP($D2,kong_np_var!$B$20:$H$26,SUBSTITUTE(N$1,"target_","") + 1,FALSE),":",$E2)) | O2: =VLOOKUP($D2,kong_np_var!$B$10:$D$16,3,FALSE) -> 172.24.148.71 | P2: =CONCATENATE("/",C2,MID(D2,2,15),"/",svc!$I2) -> /dmz504/bes_signalr_server | Q2: =VLOOKUP(C2,kong_np_var!$B$6:$C$7,2,FALSE) -> http://172.24.149.80:8001 | R2: =SUBSTITUTE(SUBSTITUTE(kong_np_var!$J$1,"<upstream_name>",$F2),"<kong_api_url>",$Q2) -> curl -X PUT http://172.24.149.80:8001/upstreams/ups-v504-bes_signalr_server | S2: =SUBSTITUTE(SUBSTITUTE(SUBSTITUTE(SUBSTITUTE(kong_np_var!$J$2,"<kong_api_url>",$Q2),"<upstream_name>",$F2),"<port>",$E2),"<service_name>",$G2) -> curl -X PUT http://172.24.149.80:8001/services/svc-v504-bes_signalr_server -H "Content-Type: application/json" -d '{"protocol":"http","host":"ups-v504-bes_signalr_server","port":31011}' | T2: =SUBSTITUTE(SUBSTITUTE(SUBSTITUTE(SUBSTITUTE(SUBSTITUTE(kong_np_var!$J$3,"<kong_api_url>",$Q2),"<route_name>",$H2),"<service_name>",$G2),"<host>",$O2),"<path>",$P2) -> curl -X PUT http://172.24.149.80:8001/services/svc-v504-bes_signalr_server/routes/route-v510-v504-bes_signalr_server -H "Content-Type: application/json" -d '{"protocols":["http"],"hosts":["172.24.148.71"],"paths":["/dmz504/bes_signalr_server"]}' | U2: =IF(I2="","","curl -X POST " & $Q2 & "/upstreams/"& $F2 &"/targets -d 'target="& I2 & "'") -> curl -X POST http://172.24.149.80:8001/upstreams/ups-v504-bes_signalr_server/targets -d 'target=172.24.148.102:31011' | V2: =IF(J2="","","curl -X POST " & $Q2 & "/upstreams/"& $F2 &"/targets -d 'target="& J2 & "'") -> curl -X POST http://172.24.149.80:8001/upstreams/ups-v504-bes_signalr_server/targets -d 'target=172.24.148.103:31011' | W2: =IF(K2="","","curl -X POST " & $Q2 & "/upstreams/"& $F2 &"/targets -d 'target="& K2 & "'") -> curl -X POST http://172.24.149.80:8001/upstreams/ups-v504-bes_signalr_server/targets -d 'target=172.24.148.104:31011' | X2: =IF(L2="","","curl -X POST " & $Q2 & "/upstreams/"& $F2 &"/targets -d 'target="& L2 & "'") | Y2: =IF(M2="","","curl -X POST " & $Q2 & "/upstreams/"& $F2 &"/targets -d 'target="& M2 & "'") | Z2: =IF(N2="","","curl -X POST " & $Q2 & "/upstreams/"& $F2 &"/targets -d 'target="& N2 & "'")
A3: =IF(ISNUMBER(SEARCH("rest_api",svc!R3)),1,0) -> 1 | C3: =svc!D3 -> dmz | D3: =svc!$B3 -> v504 | E3: =svc!G3 -> 31026 | F3: =CONCATENATE("ups-",svc!$B3,"-",svc!I3) -> ups-v504-bes_wmm | G3: =CONCATENATE("svc-",svc!$B3,"-",svc!I3) -> svc-v504-bes_wmm | H3: =CONCATENATE("route-",VLOOKUP($D3,kong_np_var!$B$10:$D$16,2,FALSE),"-",svc!$B3,"-",svc!I3) -> route-v510-v504-bes_wmm | I3: =CONCATENATE(VLOOKUP($D3,kong_np_var!$B$20:$H$26,SUBSTITUTE(I$1,"target_","") + 1,FALSE),":",$E3) -> 172.24.148.102:31026 | J3: =CONCATENATE(VLOOKUP($D3,kong_np_var!$B$20:$H$26,SUBSTITUTE(J$1,"target_","") + 1,FALSE),":",$E3) -> 172.24.148.103:31026 | K3: =CONCATENATE(VLOOKUP($D3,kong_np_var!$B$20:$H$26,SUBSTITUTE(K$1,"target_","") + 1,FALSE),":",$E3) -> 172.24.148.104:31026 | L3: =IF($C3="dmz","",CONCATENATE(VLOOKUP($D3,kong_np_var!$B$20:$H$26,SUBSTITUTE(L$1,"target_","") + 1,FALSE),":",$E3)) | M3: =IF($C3="dmz","",CONCATENATE(VLOOKUP($D3,kong_np_var!$B$20:$H$26,SUBSTITUTE(M$1,"target_","") + 1,FALSE),":",$E3)) | N3: =IF($C3="dmz","",CONCATENATE(VLOOKUP($D3,kong_np_var!$B$20:$H$26,SUBSTITUTE(N$1,"target_","") + 1,FALSE),":",$E3)) | O3: =VLOOKUP($D3,kong_np_var!$B$10:$D$16,3,FALSE) -> 172.24.148.71 | P3: =CONCATENATE("/",C3,MID(D3,2,15),"/",svc!$I3) -> /dmz504/bes_wmm | Q3: =VLOOKUP(C3,kong_np_var!$B$6:$C$7,2,FALSE) -> http://172.24.149.80:8001 | R3: =SUBSTITUTE(SUBSTITUTE(kong_np_var!$J$1,"<upstream_name>",$F3),"<kong_api_url>",$Q3) -> curl -X PUT http://172.24.149.80:8001/upstreams/ups-v504-bes_wmm | S3: =SUBSTITUTE(SUBSTITUTE(SUBSTITUTE(SUBSTITUTE(kong_np_var!$J$2,"<kong_api_url>",$Q3),"<upstream_name>",$F3),"<port>",$E3),"<service_name>",$G3) -> curl -X PUT http://172.24.149.80:8001/services/svc-v504-bes_wmm -H "Content-Type: application/json" -d '{"protocol":"http","host":"ups-v504-bes_wmm","port":31026}' | T3: =SUBSTITUTE(SUBSTITUTE(SUBSTITUTE(SUBSTITUTE(SUBSTITUTE(kong_np_var!$J$3,"<kong_api_url>",$Q3),"<route_name>",$H3),"<service_name>",$G3),"<host>",$O3),"<path>",$P3) -> curl -X PUT http://172.24.149.80:8001/services/svc-v504-bes_wmm/routes/route-v510-v504-bes_wmm -H "Content-Type: application/json" -d '{"protocols":["http"],"hosts":["172.24.148.71"],"paths":["/dmz504/bes_wmm"]}' | U3: =IF(I3="","","curl -X POST " & $Q3 & "/upstreams/"& $F3 &"/targets -d 'target="& I3 & "'") -> curl -X POST http://172.24.149.80:8001/upstreams/ups-v504-bes_wmm/targets -d 'target=172.24.148.102:31026' | V3: =IF(J3="","","curl -X POST " & $Q3 & "/upstreams/"& $F3 &"/targets -d 'target="& J3 & "'") -> curl -X POST http://172.24.149.80:8001/upstreams/ups-v504-bes_wmm/targets -d 'target=172.24.148.103:31026' | W3: =IF(K3="","","curl -X POST " & $Q3 & "/upstreams/"& $F3 &"/targets -d 'target="& K3 & "'") -> curl -X POST http://172.24.149.80:8001/upstreams/ups-v504-bes_wmm/targets -d 'target=172.24.148.104:31026' | X3: =IF(L3="","","curl -X POST " & $Q3 & "/upstreams/"& $F3 &"/targets -d 'target="& L3 & "'") | Y3: =IF(M3="","","curl -X POST " & $Q3 & "/upstreams/"& $F3 &"/targets -d 'target="& M3 & "'") | Z3: =IF(N3="","","curl -X POST " & $Q3 & "/upstreams/"& $F3 &"/targets -d 'target="& N3 & "'")
A4: =IF(ISNUMBER(SEARCH("rest_api",svc!R4)),1,0) -> 1 | C4: =svc!D4 -> dmz | D4: =svc!$B4 -> v804 | E4: =svc!G4 -> 31026 | F4: =CONCATENATE("ups-",svc!$B4,"-",svc!I4) -> ups-v804-bes_wmm | G4: =CONCATENATE("svc-",svc!$B4,"-",svc!I4) -> svc-v804-bes_wmm | H4: =CONCATENATE("route-",VLOOKUP($D4,kong_np_var!$B$10:$D$16,2,FALSE),"-",svc!$B4,"-",svc!I4) -> route-v810-v804-bes_wmm | I4: =CONCATENATE(VLOOKUP($D4,kong_np_var!$B$20:$H$26,SUBSTITUTE(I$1,"target_","") + 1,FALSE),":",$E4) -> 172.24.149.70:31026 | J4: =CONCATENATE(VLOOKUP($D4,kong_np_var!$B$20:$H$26,SUBSTITUTE(J$1,"target_","") + 1,FALSE),":",$E4) -> 172.24.149.71:31026 | K4: =CONCATENATE(VLOOKUP($D4,kong_np_var!$B$20:$H$26,SUBSTITUTE(K$1,"target_","") + 1,FALSE),":",$E4) -> 172.24.149.72:31026 | L4: =IF($C4="dmz","",CONCATENATE(VLOOKUP($D4,kong_np_var!$B$20:$H$26,SUBSTITUTE(L$1,"target_","") + 1,FALSE),":",$E4)) | M4: =IF($C4="dmz","",CONCATENATE(VLOOKUP($D4,kong_np_var!$B$20:$H$26,SUBSTITUTE(M$1,"target_","") + 1,FALSE),":",$E4)) | N4: =IF($C4="dmz","",CONCATENATE(VLOOKUP($D4,kong_np_var!$B$20:$H$26,SUBSTITUTE(N$1,"target_","") + 1,FALSE),":",$E4)) | O4: =VLOOKUP($D4,kong_np_var!$B$10:$D$16,3,FALSE) -> 172.24.151.71 | P4: =CONCATENATE("/",C4,MID(D4,2,15),"/",svc!$I4) -> /dmz804/bes_wmm | Q4: =VLOOKUP(C4,kong_np_var!$B$6:$C$7,2,FALSE) -> http://172.24.149.80:8001 | R4: =SUBSTITUTE(SUBSTITUTE(kong_np_var!$J$1,"<upstream_name>",$F4),"<kong_api_url>",$Q4) -> curl -X PUT http://172.24.149.80:8001/upstreams/ups-v804-bes_wmm | S4: =SUBSTITUTE(SUBSTITUTE(SUBSTITUTE(SUBSTITUTE(kong_np_var!$J$2,"<kong_api_url>",$Q4),"<upstream_name>",$F4),"<port>",$E4),"<service_name>",$G4) -> curl -X PUT http://172.24.149.80:8001/services/svc-v804-bes_wmm -H "Content-Type: application/json" -d '{"protocol":"http","host":"ups-v804-bes_wmm","port":31026}' | T4: =SUBSTITUTE(SUBSTITUTE(SUBSTITUTE(SUBSTITUTE(SUBSTITUTE(kong_np_var!$J$3,"<kong_api_url>",$Q4),"<route_name>",$H4),"<service_name>",$G4),"<host>",$O4),"<path>",$P4) -> curl -X PUT http://172.24.149.80:8001/services/svc-v804-bes_wmm/routes/route-v810-v804-bes_wmm -H "Content-Type: application/json" -d '{"protocols":["http"],"hosts":["172.24.151.71"],"paths":["/dmz804/bes_wmm"]}' | U4: =IF(I4="","","curl -X POST " & $Q4 & "/upstreams/"& $F4 &"/targets -d 'target="& I4 & "'") -> curl -X POST http://172.24.149.80:8001/upstreams/ups-v804-bes_wmm/targets -d 'target=172.24.149.70:31026' | V4: =IF(J4="","","curl -X POST " & $Q4 & "/upstreams/"& $F4 &"/targets -d 'target="& J4 & "'") -> curl -X POST http://172.24.149.80:8001/upstreams/ups-v804-bes_wmm/targets -d 'target=172.24.149.71:31026' | W4: =IF(K4="","","curl -X POST " & $Q4 & "/upstreams/"& $F4 &"/targets -d 'target="& K4 & "'") -> curl -X POST http://172.24.149.80:8001/upstreams/ups-v804-bes_wmm/targets -d 'target=172.24.149.72:31026' | X4: =IF(L4="","","curl -X POST " & $Q4 & "/upstreams/"& $F4 &"/targets -d 'target="& L4 & "'") | Y4: =IF(M4="","","curl -X POST " & $Q4 & "/upstreams/"& $F4 &"/targets -d 'target="& M4 & "'") | Z4: =IF(N4="","","curl -X POST " & $Q4 & "/upstreams/"& $F4 &"/targets -d 'target="& N4 & "'")
A5: =IF(ISNUMBER(SEARCH("rest_api",svc!R5)),1,0) -> 0 | C5: =svc!D5 -> dmz | D5: =svc!$B5 -> v504 | E5: =svc!G5 -> 31010 | F5: =CONCATENATE("ups-",svc!$B5,"-",svc!I5) -> ups-v504-bescore_portal | G5: =CONCATENATE("svc-",svc!$B5,"-",svc!I5) -> svc-v504-bescore_portal | H5: =CONCATENATE("route-",VLOOKUP($D5,kong_np_var!$B$10:$D$16,2,FALSE),"-",svc!$B5,"-",svc!I5) -> route-v510-v504-bescore_portal | I5: =CONCATENATE(VLOOKUP($D5,kong_np_var!$B$20:$H$26,SUBSTITUTE(I$1,"target_","") + 1,FALSE),":",$E5) -> 172.24.148.102:31010 | J5: =CONCATENATE(VLOOKUP($D5,kong_np_var!$B$20:$H$26,SUBSTITUTE(J$1,"target_","") + 1,FALSE),":",$E5) -> 172.24.148.103:31010 | K5: =CONCATENATE(VLOOKUP($D5,kong_np_var!$B$20:$H$26,SUBSTITUTE(K$1,"target_","") + 1,FALSE),":",$E5) -> 172.24.148.104:31010 | L5: =IF($C5="dmz","",CONCATENATE(VLOOKUP($D5,kong_np_var!$B$20:$H$26,SUBSTITUTE(L$1,"target_","") + 1,FALSE),":",$E5)) | M5: =IF($C5="dmz","",CONCATENATE(VLOOKUP($D5,kong_np_var!$B$20:$H$26,SUBSTITUTE(M$1,"target_","") + 1,FALSE),":",$E5)) | N5: =IF($C5="dmz","",CONCATENATE(VLOOKUP($D5,kong_np_var!$B$20:$H$26,SUBSTITUTE(N$1,"target_","") + 1,FALSE),":",$E5)) | O5: =VLOOKUP($D5,kong_np_var!$B$10:$D$16,3,FALSE) -> 172.24.148.71 | P5: =CONCATENATE("/",C5,MID(D5,2,15),"/",svc!$I5) -> /dmz504/bescore_portal | Q5: =VLOOKUP(C5,kong_np_var!$B$6:$C$7,2,FALSE) -> http://172.24.149.80:8001 | R5: =SUBSTITUTE(SUBSTITUTE(kong_np_var!$J$1,"<upstream_name>",$F5),"<kong_api_url>",$Q5) -> curl -X PUT http://172.24.149.80:8001/upstreams/ups-v504-bescore_portal | S5: =SUBSTITUTE(SUBSTITUTE(SUBSTITUTE(SUBSTITUTE(kong_np_var!$J$2,"<kong_api_url>",$Q5),"<upstream_name>",$F5),"<port>",$E5),"<service_name>",$G5) -> curl -X PUT http://172.24.149.80:8001/services/svc-v504-bescore_portal -H "Content-Type: application/json" -d '{"protocol":"http","host":"ups-v504-bescore_portal","port":31010}' | T5: =SUBSTITUTE(SUBSTITUTE(SUBSTITUTE(SUBSTITUTE(SUBSTITUTE(kong_np_var!$J$3,"<kong_api_url>",$Q5),"<route_name>",$H5),"<service_name>",$G5),"<host>",$O5),"<path>",$P5) -> curl -X PUT http://172.24.149.80:8001/services/svc-v504-bescore_portal/routes/route-v510-v504-bescore_portal -H "Content-Type: application/json" -d '{"protocols":["http"],"hosts":["172.24.148.71"],"paths":["/dmz504/bescore_portal"]}' | U5: =IF(I5="","","curl -X POST " & $Q5 & "/upstreams/"& $F5 &"/targets -d 'target="& I5 & "'") -> curl -X POST http://172.24.149.80:8001/upstreams/ups-v504-bescore_portal/targets -d 'target=172.24.148.102:31010' | V5: =IF(J5="","","curl -X POST " & $Q5 & "/upstreams/"& $F5 &"/targets -d 'target="& J5 & "'") -> curl -X POST http://172.24.149.80:8001/upstreams/ups-v504-bescore_portal/targets -d 'target=172.24.148.103:31010' | W5: =IF(K5="","","curl -X POST " & $Q5 & "/upstreams/"& $F5 &"/targets -d 'target="& K5 & "'") -> curl -X POST http://172.24.149.80:8001/upstreams/ups-v504-bescore_portal/targets -d 'target=172.24.148.104:31010' | X5: =IF(L5="","","curl -X POST " & $Q5 & "/upstreams/"& $F5 &"/targets -d 'target="& L5 & "'") | Y5: =IF(M5="","","curl -X POST " & $Q5 & "/upstreams/"& $F5 &"/targets -d 'target="& M5 & "'") | Z5: =IF(N5="","","curl -X POST " & $Q5 & "/upstreams/"& $F5 &"/targets -d 'target="& N5 & "'")
